// Copyright (C) 2017 Ecma International.  All rights reserved.
// This code is governed by the BSD license found in the LICENSE file.
/*---
description: |
    Collection of assertion functions used throughout test262
defines: [assert]
---*/


function assert(mustBeTrue, message) {
    if (mustBeTrue === true) {
        return;
    }

    if (message === undefined) {
        message = 'Expected true but got ' + assert._toString(mustBeTrue);
    }
    throw message;
}

assert._isSameValue = function (a, b) {
    var same;
    if (a === b) {
        // Handle +/-0 vs. -/+0
        same = a !== 0 || 1 / a === 1 / b;
    } else {
        // Handle NaN vs. NaN
        same = a !== a && b !== b;
    }
    if (!same) {
        throw a + " does not equal " + b;
    }
    return true;
};

assert.sameValue = function (actual, expected, message) {
    try {
        if (assert._isSameValue(actual, expected)) {
            return;
        }
    } catch (error) {
        throw message + ' (_isSameValue operation threw) ' + error;
    }

    if (message === undefined) {
        message = '';
    } else {
        message += ' ';
    }

    throw message += 'Expected SameValue(«' + assert._toString(actual) + '», «' + assert._toString(expected) + '») to be true';
};

assert.notSameValue = function (actual, unexpected, message) {
    if (!assert._isSameValue(actual, unexpected)) {
        return;
    }

    if (message === undefined) {
        message = '';
    } else {
        message += ' ';
    }

    message += 'Expected SameValue(«' + assert._toString(actual) + '», «' + assert._toString(unexpected) + '») to be false';

    throw message;
};

assert.throws = function (expectedErrorConstructor, func, message) {
    if (typeof func !== "function") {
        throw 'assert.throws requires two arguments: the error constructor ' +
            'and a function to run';
    }
    if (message === undefined) {
        message = '';
    } else {
        message += ' ';
    }

    try {
        func();
    } catch (thrown) {
        if (typeof thrown !== 'object' || thrown === null) {
            message += 'Thrown value was not an object!';
            throw message;
        } else if (thrown.constructor !== expectedErrorConstructor) {
            message += 'Expected a ' + expectedErrorConstructor.name + ' but got a ' + thrown.constructor.name;
            throw message;
        }
        return;
    }

    message += 'Expected a ' + expectedErrorConstructor.name + ' to be thrown but no exception was thrown at all';
    throw message;
};

assert._toString = function (value) {
    try {
        if (value === 0 && 1 / value === -Infinity) {
            return '-0';
        }

        return String(value);
    } catch (err) {
        if (err.name === 'TypeError') {
            return Object.prototype.toString.call(value);
        }

        throw err;
    }
};// This file was procedurally generated from the following sources:
// - src/async-generators/yield-promise-reject-next-for-await-of-async-iterator.case
// - src/async-generators/default/async-class-decl-private-method.template
/*---
description: yield * [Promise.reject(value)] is treated as throw value (Async Generator method as a ClassDeclaration element)
esid: prod-AsyncGeneratorPrivateMethod
features: [async-iteration, class-methods-private]
flags: [generated, async]
info: |
    ClassElement :
      PrivateMethodDefinition

    MethodDefinition :
      AsyncGeneratorMethod

    Async Generator Function Definitions

    AsyncGeneratorMethod :
      async [no LineTerminator here] * PropertyName ( UniqueFormalParameters ) { AsyncGeneratorBody }

---*/
let error = new Error();
async function * readFile() {
  yield Promise.reject(error);
  yield "unreachable";
}


var callCount = 0;

class C {
    async *#gen() {
        callCount += 1;
        for await (let line of readFile()) {
          yield line;
        }
    }
    get gen() { return this.#gen; }
}

const c = new C();

// Test the private fields do not appear as properties before set to value
assert.sameValue(Object.hasOwnProperty.call(C.prototype, "#gen"), false, 'Object.hasOwnProperty.call(C.prototype, "#gen")');
assert.sameValue(Object.hasOwnProperty.call(C, "#gen"), false, 'Object.hasOwnProperty.call(C, "#gen")');
assert.sameValue(Object.hasOwnProperty.call(c, "#gen"), false, 'Object.hasOwnProperty.call(c, "#gen")');

var iter = c.gen();

iter.next().then(() => {
  throw new Test262Error("Promise incorrectly resolved.");
}, rejectValue => {

  // yield Promise.reject(error);
  assert.sameValue(rejectValue, error);

  iter.next().then(({done, value}) => {
    // iter is closed now.
    assert.sameValue(done, true, "The value of IteratorResult.done is `true`");
    assert.sameValue(value, undefined, "The value of IteratorResult.value is `undefined`");
  }).then($DONE, $DONE);
}).catch($DONE);

assert.sameValue(callCount, 1);

// Test the private fields do not appear as properties after set to value
assert.sameValue(Object.hasOwnProperty.call(C.prototype, "#gen"), false, 'Object.hasOwnProperty.call(C.prototype, "#gen")');
assert.sameValue(Object.hasOwnProperty.call(C, "#gen"), false, 'Object.hasOwnProperty.call(C, "#gen")');
assert.sameValue(Object.hasOwnProperty.call(c, "#gen"), false, 'Object.hasOwnProperty.call(c, "#gen")');
